<?xml version="1.0" ?>
<!-- =================================================================================== -->
<!-- |    This document was autogenerated by xacro from servo6dof.urdf.xacro           | -->
<!-- |    EDITING THIS FILE BY HAND IS NOT RECOMMENDED                                 | -->
<!-- =================================================================================== -->
<robot name="servo6dof">
  <link name="world"/>
  <link name="base_link">
    <visual>
      <origin rpy="0 0 0" xyz="0.25 0.25 0"/>
      <geometry>
        <mesh filename="package://servo6dof/meshes/basement.stl" scale="6 6 6"/>
      </geometry>
    </visual>
  </link>
  <joint name="virtual_joint" type="fixed">
    <parent link="world"/>
    <child link="base_link"/>
    <origin rpy="0 0 0" xyz="0 0 0"/>
  </joint>
  <link name="primeiro_elo">
    <visual>
      <origin rpy="0 0 0" xyz="0.25 0.57 0"/>
      <geometry>
        <mesh filename="package://servo6dof/meshes/manipulator_elo1.stl" scale="6 6 6"/>
      </geometry>
    </visual>
  </link>
  <joint name="joint_1" type="revolute">
    <parent link="base_link"/>
    <child link="primeiro_elo"/>
    <axis xyz="0 0 1"/>
    <origin rpy="0 0 0" xyz="0 -0.23 -0.01"/>
    <limit effort="30.0" lower="-1.570795" upper="1.570795" velocity="10.0"/>
  </joint>
  <link name="segundo_elo">
    <visual>
      <origin rpy="0 0 0" xyz="0.3 0.6 -0.55"/>
      <geometry>
        <mesh filename="package://servo6dof/meshes/manipulator_elo2.stl" scale="6 6 6"/>
      </geometry>
    </visual>
  </link>
  <joint name="joint_2" type="revolute">
    <parent link="primeiro_elo"/>
    <child link="segundo_elo"/>
    <axis xyz="1 0 0"/>
    <origin rpy="0 0 0" xyz="-0.05 -0.03 0.57"/>
    <limit effort="30.0" lower="-1.570795" upper="1.570795" velocity="10.0"/>
  </joint>
  <link name="terceiro_elo">
    <visual>
      <origin rpy="0 0 0" xyz="0.25 0.6 -1.18"/>
      <geometry>
        <mesh filename="package://servo6dof/meshes/manipulator_elo3.stl" scale="6 6 6"/>
      </geometry>
    </visual>
  </link>
  <joint name="joint_3" type="revolute">
    <parent link="segundo_elo"/>
    <child link="terceiro_elo"/>
    <axis xyz="1 0 0"/>
    <origin rpy="0 0 0" xyz="0.06 0 0.63"/>
    <limit effort="30.0" lower="-1.570795" upper="1.570795" velocity="10.0"/>
  </joint>
  <link name="quarto_elo">
    <visual>
      <origin rpy="0 0 0" xyz="0.25 -0.187 -1.18"/>
      <geometry>
        <mesh filename="package://servo6dof/meshes/manipulator_elo4.stl" scale="6 6 6"/>
      </geometry>
    </visual>
  </link>
  <joint name="joint_4" type="revolute">
    <parent link="terceiro_elo"/>
    <child link="quarto_elo"/>
    <axis xyz="1 0 0"/>
    <origin rpy="0 0 0" xyz="0 0.78 0"/>
    <limit effort="30.0" lower="-1.570795" upper="1.570795" velocity="10.0"/>
  </joint>
  <link name="base_garra">
    <visual>
      <origin rpy="0 0 1.570795" xyz="0 0 0"/>
      <geometry>
        <mesh filename="package://servo6dof/meshes/base_garra.stl" scale="6 6 6"/>
      </geometry>
    </visual>
  </link>
  <joint name="joint_5" type="revolute">
    <parent link="quarto_elo"/>
    <child link="base_garra"/>
    <axis xyz="0 1 0"/>
    <origin rpy="0 0 0" xyz="0.02 0.36 0"/>
    <limit effort="30.0" lower="-1.570795" upper="1.570795" velocity="10.0"/>
  </joint>
  <link name="garra_elo1">
    <visual>
      <origin rpy="0 3.14159 -1.570795" xyz="0.07 -0.15 0.05"/>
      <geometry>
        <mesh filename="package://servo6dof/meshes/garra_elo1.stl" scale="6 6 6"/>
      </geometry>
    </visual>
  </link>
  <joint name="joint_6" type="revolute">
    <parent link="base_garra"/>
    <child link="garra_elo1"/>
    <axis xyz="0 0 1"/>
    <origin rpy="0 0 0" xyz="-0.072 0.12 0.01"/>
    <limit effort="30.0" lower="-0.6981311111111111" upper="0.5235983333333333" velocity="10.0"/>
  </joint>
  <link name="garra_elo2a">
    <visual>
      <origin rpy="0 0 0" xyz="-0.403 0.133 0"/>
      <geometry>
        <mesh filename="package://servo6dof/meshes/garra_elo2.stl" scale="6 6 6"/>
      </geometry>
    </visual>
  </link>
  <joint name="joint_garra_1" type="revolute">
    <parent link="base_garra"/>
    <child link="garra_elo2a"/>
    <axis xyz="0 0 1"/>
    <origin rpy="0 0 0" xyz="-0.05 0.27 0.01"/>
    <mimic joint="joint_6" multiplier="1" offset="-0.2"/>
    <limit effort="30.0" lower="-1.570795" upper="1.570795" velocity="10.0"/>
  </joint>
  <link name="garra_elo3a">
    <visual>
      <origin rpy="0 3.14159 0" xyz="0.28 0.205 0"/>
      <geometry>
        <mesh filename="package://servo6dof/meshes/garra_pinca.stl" scale="6 6 6"/>
      </geometry>
    </visual>
  </link>
  <joint name="joint_pinca_a" type="revolute">
    <parent link="garra_elo1"/>
    <child link="garra_elo3a"/>
    <axis xyz="0 0 1"/>
    <origin rpy="0 0 -1.570795" xyz="-0.13 0.13 0"/>
    <mimic joint="joint_6" multiplier="-1" offset="0.2"/>
    <limit effort="30.0" velocity="10.0"/>
  </joint>
  <link name="garra_elo2">
    <visual>
      <origin rpy="0 0 1.570795" xyz="-0.07 -0.15 -0.03"/>
      <geometry>
        <mesh filename="package://servo6dof/meshes/garra_elo1.stl" scale="6 6 6"/>
      </geometry>
    </visual>
  </link>
  <joint name="joint_7" type="revolute">
    <parent link="base_garra"/>
    <child link="garra_elo2"/>
    <axis xyz="0 0 1"/>
    <origin rpy="0 0 0" xyz="+0.072 0.12 0.01"/>
    <mimic joint="joint_6" multiplier="-1" offset="0"/>
    <limit effort="30.0" lower="-0.5235983333333333" upper="0.5235983333333333" velocity="10.0"/>
  </joint>
  <link name="garra_elo2b">
    <visual>
      <origin rpy="0 0 3.14159" xyz="0.273 -0.036 0"/>
      <geometry>
        <mesh filename="package://servo6dof/meshes/garra_elo2.stl" scale="6 6 6"/>
      </geometry>
    </visual>
  </link>
  <joint name="joint_garra_3" type="revolute">
    <parent link="base_garra"/>
    <child link="garra_elo2b"/>
    <axis xyz="0 0 1"/>
    <origin rpy="0 0 0" xyz="+0.04 0.27 0.01"/>
    <mimic joint="joint_6" multiplier="-1" offset="-1.6708"/>
    <limit effort="30.0" lower="-1.570795" upper="1.570795" velocity="10.0"/>
  </joint>
  <link name="garra_elo3b">
    <visual>
      <origin rpy="0 0 0" xyz="-0.285 0.205 0"/>
      <geometry>
        <mesh filename="package://servo6dof/meshes/garra_pinca.stl" scale="6 6 6"/>
      </geometry>
    </visual>
  </link>
  <joint name="joint_pinca_b" type="revolute">
    <parent link="garra_elo2"/>
    <child link="garra_elo3b"/>
    <axis xyz="0 0 1"/>
    <origin rpy="0 0 1.570795" xyz="0.13 0.13 0"/>
    <mimic joint="joint_6" multiplier="1" offset="-0.2"/>
    <limit effort="30.0" velocity="10.0"/>
  </joint>
</robot>
