<?xml version="1.0"?>


<robot xmlns:xacro="http://www.ros.org/wiki/xacro" name="servo6dof">
	
	<xacro:property name="PI" value="3.14159"/>
	<xacro:property name="effort" value="30.0"/>
	<xacro:property name="velocity" value="10.0"/>

	<link name="world"/>
	<link name="base_link">
		<visual>
			<origin rpy="0 0 0" xyz="0.25 0.25 0"/>
			<geometry>
				<mesh filename="package://servo6dof/meshes/basement.stl" scale="6 6 6"/>
			</geometry>
		</visual>
	</link>
	<joint name="virtual_joint" type="fixed">
		<parent link="world"/>
		<child link="base_link"/>
		<origin rpy="0 0 0" xyz="0 0 0"/>
	</joint>

	<link name="primeiro_elo">
		<visual>
			<origin rpy="0 0 0" xyz="0.25 0.57 0"/>
			<geometry>
				<mesh filename="package://servo6dof/meshes/manipulator_elo1.stl" scale="6 6 6"/>
			</geometry>
		</visual>
	</link>
	<joint name="joint_1" type="revolute">
		<parent link="base_link"/>
		<child link="primeiro_elo"/>
		<axis xyz="0 0 1"/>
		<origin rpy="0 0 -${PI/2}" xyz="0 -0.23 -0.01"/>
		<limit lower="0" upper="${PI}" effort="${effort}" velocity="${velocity}"/>
	</joint>
	<link name="segundo_elo">
		<visual>
			<origin rpy="0 0 0" xyz="0.3 0.6 -0.55"/>
			<geometry>
				<mesh filename="package://servo6dof/meshes/manipulator_elo2.stl" scale="6 6 6"/>
			</geometry>
		</visual>
	</link>
	<joint name="joint_2" type="revolute">
		<parent link="primeiro_elo"/>
		<child link="segundo_elo"/>
		<axis xyz="1 0 0"/>
		<origin rpy="0 0 0" xyz="-0.05 -0.03 0.57"/>
		<limit lower="-${PI/2}" upper="${PI/2}" effort="${effort}" velocity="${velocity}"/>
	</joint>

	<link name="terceiro_elo">
		<visual>
			<origin rpy="0 0 0" xyz="0.25 0.6 -1.18"/>
			<geometry>
				<mesh filename="package://servo6dof/meshes/manipulator_elo3.stl" scale="6 6 6"/>
			</geometry>
		</visual>
	</link>
	<joint name="joint_3" type="revolute">
		<parent link="segundo_elo"/>
		<child link="terceiro_elo"/>
		<axis xyz="1 0 0"/>
		<origin rpy="0 0 0" xyz="0.06 0 0.63"/>
		<limit lower="-${PI/2}" upper="${PI/2}" effort="${effort}" velocity="${velocity}"/>
	</joint>

	<link name="quarto_elo">
		<visual>
			<origin rpy="0 0 0" xyz="0.25 -0.187 -1.18"/>
			<geometry>
				<mesh filename="package://servo6dof/meshes/manipulator_elo4.stl" scale="6 6 6"/>
			</geometry>
		</visual>
	</link>
	<joint name="joint_4" type="revolute">
		<parent link="terceiro_elo"/>
		<child link="quarto_elo"/>
		<axis xyz="1 0 0"/>
		<origin rpy="0 0 0" xyz="0 0.78 0"/>
		<limit lower="-${PI/2}" upper="${PI/2}" effort="${effort}" velocity="${velocity}"/>
	</joint>

	<link name="base_garra">
		<visual>
			<origin rpy="0 0 ${PI/2}" xyz="0 0 0"/>
			<geometry>
				<mesh filename="package://servo6dof/meshes/base_garra.stl" scale="6 6 6"/>
			</geometry>
		</visual>
	</link>
	<joint name="joint_5" type="revolute">
		<parent link="quarto_elo"/>
		<child link="base_garra"/>
		<axis xyz="0 1 0"/>
		<origin rpy="0 0 0" xyz="0.02 0.36 0"/>
		<limit lower="-${PI/2}" upper="${PI/2}" effort="${effort}" velocity="${velocity}"/>
	</joint>

	<link name="garra_elo1">
		<visual>
			<origin rpy="0 ${PI} -${PI/2}" xyz="0.07 -0.15 0.05"/>
			<geometry>
				<mesh filename="package://servo6dof/meshes/garra_elo1.stl" scale="6 6 6"/>
			</geometry>
		</visual>
	</link>
	<joint name="joint_6" type="revolute">
		<parent link="base_garra"/>
		<child link="garra_elo1"/>
		<axis xyz="0 0 1"/>
		<origin rpy="0 0 0" xyz="-0.085 0.17 0.01"/>
		<limit lower="-${PI/2}" upper="${PI/2}" effort="${effort}" velocity="${velocity}"/>
	</joint>

	<link name="garra_elo2a">
		<visual>
			<origin rpy="0 0 0" xyz="0 0 0"/>
			<geometry>
				<mesh filename="package://servo6dof/meshes/garra_elo2.stl" scale="6 6 6"/>
			</geometry>
		</visual>
	</link>
	<joint name="joint_garra_1" type="revolute">
		<parent link="base_garra"/>
		<child link="garra_elo2a"/>
		<axis xyz="0 0 1"/>
		<origin rpy="0 0 0" xyz="-0.085 0.4 0.01"/>
		<mimic joint="joint_6" multiplier="1" offset="0" />
		<limit lower="-${PI/2}" upper="${PI/2}" effort="${effort}" velocity="${velocity}"/>
	</joint>
</robot>
